Workbook

Sheet Reference
A1: Campaign | B1: Venue | C1: Week Ending Date | D1: Pay Period | E1: Position Type | F1: Position's Base Hourly Pay Rate
A2: Campaign A | B2: Door | C2: 46038 | D2: 46038 | E2: Canvasser | F2: 24
A3: Campaign A | B3: Door | C3: 46045 | D3: 46052 | E3: Canvasser | F3: 24
A4: Campaign A | B4: Door | C4: 46052 | D4: 46052 | E4: Canvasser | F4: 24
A5: Campaign A | B5: Door | C5: 46059 | D5: 46066 | E5: Canvasser | F5: 25
A6: Campaign A | B6: Door | C6: 46066 | D6: 46066 | E6: Canvasser | F6: 25
A7: Campaign A | B7: Door | C7: 46073 | D7: 46080 | E7: Canvasser | F7: 25
A8: Campaign A | B8: Door | C8: 46080 | D8: 46080 | E8: Canvasser | F8: 25
A9: Campaign A | B9: Door | C9: 46038 | D9: 46038 | E9: Team Lead | F9: 26
A10: Campaign A | B10: Door | C10: 46045 | D10: 46052 | E10: Team Lead | F10: 26
A11: Campaign A | B11: Door | C11: 46052 | D11: 46052 | E11: Team Lead | F11: 27
A12: Campaign A | B12: Door | C12: 46059 | D12: 46066 | E12: Team Lead | F12: 27
A13: Campaign A | B13: Door | C13: 46066 | D13: 46066 | E13: Team Lead | F13: 27
... A36: Campaign B | B36: Door | C36: 46080 | D36: 46080 | E36: Team Lead | F36: 26

Sheet Data
A1: Office | B1: Canvass Date | C1: Canvasser | D1: Position | E1: Campaign | F1: Venue | G1: Shift Type | H1: Team Lead | I1: Clock In | J1: Clock Out | K1: Unpaid Break Time (In Mins) | L1: Canvassing Start Time | M1: Canvassing End Time | N1: Total Paid Break Time While Canvassing (In Mins) | O1: Shifts Credited | P1: Knocks | Q1: Week End Date Per Shift | R1: Total Paid Hours | S1: Hourly Rate | T1: Base Pay | U1: Total Canvassing Hours | V1: Total Knocks Per Canvassing Hour | W1: Day Of Week | X1: Friday Or Saturday Bonus | Y1: Pay Period | Z1: Weekly Canvassing Hours | AA1: Weekly Bonus | AB1: Total Pay | AC1: Data Issues
A2: Washington | B2: 46036 | C2: Maya Patel | D2: Canvasser | E2: Campaign A | F2: Door | G2: No Field Time | I2: 0.39583333 | J2: 0.57638889 | K2: 0 | O2: 0 | P2: 0 | Q2: =B2+MOD(6-WEEKDAY(B2,1),7) -> 46038 | R2: =IF(OR(I2="", J2=""),0,(J2-I2)*24-K2/60) -> 4.3333333 | S2: =IFERROR(__xludf.DUMMYFUNCTION("IFERROR( INDEX( FILTER( Reference!$F:$F, Reference!$A:$A = $E2, Reference!$E:$E = $D2, Reference!$C:$C = $Q2),1),""RATE_NOT_FOUND"")"),24.0) -> 24 | T2: =IF($S2="","", S2*R2) -> 104 | U2: =IF(OR(M2="",L2=""),0,(M2-L2)*24-N2/60) -> 0 | V2: =IF(OR(P2=0, G2="No Field Time"),0,P2/U2) -> 0 | W2: =TEXT(B2,"dddd") -> Wednesday | X2: =IF(AND(OR(W2="Friday", W2="Saturday"), V2>=18), 50, 0) -> 0 | Y2: =IFERROR(__xludf.DUMMYFUNCTION("IFERROR( INDEX( FILTER(Reference!$D:$D, Reference!$A:$A=$E2, Reference!$C:$C=$Q2), 1),"""")"),46038.0) -> 46038 | Z2: =SUMIFS( $U:$U, $C:$C, $C2, $Q:$Q, $Q2 ) -> 9.5833333 | AA2: =IF(Z2=0,0, IF(Z2>=LOOKUP(Q2,MinHr_Weekly_Bonus!A:A,MinHr_Weekly_Bonus!B:B), LOOKUP(Q2,MinHr_Weekly_Bonus!A:A,MinHr_Weekly_Bonus!C:C), 0)) -> 0 | AB2: =T2+X2 -> 104 | AC2: =IF(AND(U2<1, V2>100, U2>0),"REVIEW: very high KPH","")
A3: Washington | B3: 46036 | C3: Jordan Williams | D3: Canvasser | E3: Campaign A | F3: Door | G3: No Field Time | I3: 0.39583333 | J3: 0.57638889 | K3: 0 | O3: 0 | P3: 0 | Q3: =B3+MOD(6-WEEKDAY(B3,1),7) -> 46038 | R3: =IF(OR(I3="", J3=""),0,(J3-I3)*24-K3/60) -> 4.3333333 | S3: =IFERROR(__xludf.DUMMYFUNCTION("IFERROR( INDEX( FILTER( Reference!$F:$F, Reference!$A:$A = $E3, Reference!$E:$E = $D3, Reference!$C:$C = $Q3),1),""RATE_NOT_FOUND"")"),24.0) -> 24 | T3: =IF($S3="","", S3*R3) -> 104 | U3: =IF(OR(M3="",L3=""),0,(M3-L3)*24-N3/60) -> 0 | V3: =IF(OR(P3=0, G3="No Field Time"),0,P3/U3) -> 0 | W3: =TEXT(B3,"dddd") -> Wednesday | X3: =IF(AND(OR(W3="Friday", W3="Saturday"), V3>=18), 50, 0) -> 0 | Y3: =IFERROR(__xludf.DUMMYFUNCTION("IFERROR( INDEX( FILTER(Reference!$D:$D, Reference!$A:$A=$E3, Reference!$C:$C=$Q3), 1),"""")"),46038.0) -> 46038 | Z3: =SUMIFS( $U:$U, $C:$C, $C3, $Q:$Q, $Q3 ) -> 9.8333333 | AA3: =IF(Z3=0,0, IF(Z3>=LOOKUP(Q3,MinHr_Weekly_Bonus!A:A,MinHr_Weekly_Bonus!B:B), LOOKUP(Q3,MinHr_Weekly_Bonus!A:A,MinHr_Weekly_Bonus!C:C), 0)) -> 0 | AB3: =T3+X3 -> 104 | AC3: =IF(AND(U3<1, V3>100, U3>0),"REVIEW: very high KPH","")
A4: Washington | B4: 46036 | C4: Carlos Ramirez | D4: Canvasser | E4: Campaign A | F4: Door | G4: No Field Time | I4: 0.39583333 | J4: 0.57638889 | K4: 0 | O4: 0 | P4: 0 | Q4: =B4+MOD(6-WEEKDAY(B4,1),7) -> 46038 | R4: =IF(OR(I4="", J4=""),0,(J4-I4)*24-K4/60) -> 4.3333333 | S4: =IFERROR(__xludf.DUMMYFUNCTION("IFERROR( INDEX( FILTER( Reference!$F:$F, Reference!$A:$A = $E4, Reference!$E:$E = $D4, Reference!$C:$C = $Q4),1),""RATE_NOT_FOUND"")"),24.0) -> 24 | T4: =IF($S4="","", S4*R4) -> 104 | U4: =IF(OR(M4="",L4=""),0,(M4-L4)*24-N4/60) -> 0 | V4: =IF(OR(P4=0, G4="No Field Time"),0,P4/U4) -> 0 | W4: =TEXT(B4,"dddd") -> Wednesday | X4: =IF(AND(OR(W4="Friday", W4="Saturday"), V4>=18), 50, 0) -> 0 | Y4: =IFERROR(__xludf.DUMMYFUNCTION("IFERROR( INDEX( FILTER(Reference!$D:$D, Reference!$A:$A=$E4, Reference!$C:$C=$Q4), 1),"""")"),46038.0) -> 46038 | Z4: =SUMIFS( $U:$U, $C:$C, $C4, $Q:$Q, $Q4 ) -> 9.0833333 | AA4: =IF(Z4=0,0, IF(Z4>=LOOKUP(Q4,MinHr_Weekly_Bonus!A:A,MinHr_Weekly_Bonus!B:B), LOOKUP(Q4,MinHr_Weekly_Bonus!A:A,MinHr_Weekly_Bonus!C:C), 0)) -> 0 | AB4: =T4+X4 -> 104 | AC4: =IF(AND(U4<1, V4>100, U4>0),"REVIEW: very high KPH","")
A5: Washington | B5: 46036 | C5: Emily Chen | D5: Canvasser | E5: Campaign A | F5: Door | G5: No Field Time | I5: 0.39583333 | J5: 0.57638889 | K5: 0 | O5: 0 | P5: 0 | Q5: =B5+MOD(6-WEEKDAY(B5,1),7) -> 46038 | R5: =IF(OR(I5="", J5=""),0,(J5-I5)*24-K5/60) -> 4.3333333 | S5: =IFERROR(__xludf.DUMMYFUNCTION("IFERROR( INDEX( FILTER( Reference!$F:$F, Reference!$A:$A = $E5, Reference!$E:$E = $D5, Reference!$C:$C = $Q5),1),""RATE_NOT_FOUND"")"),24.0) -> 24 | T5: =IF($S5="","", S5*R5) -> 104 | U5: =IF(OR(M5="",L5=""),0,(M5-L5)*24-N5/60) -> 0 | V5: =IF(OR(P5=0, G5="No Field Time"),0,P5/U5) -> 0 | W5: =TEXT(B5,"dddd") -> Wednesday | X5: =IF(AND(OR(W5="Friday", W5="Saturday"), V5>=18), 50, 0) -> 0 | Y5: =IFERROR(__xludf.DUMMYFUNCTION("IFERROR( INDEX( FILTER(Reference!$D:$D, Reference!$A:$A=$E5, Reference!$C:$C=$Q5), 1),"""")"),46038.0) -> 46038 | Z5: =SUMIFS( $U:$U, $C:$C, $C5, $Q:$Q, $Q5 ) -> 2.0833333 | AA5: =IF(Z5=0,0, IF(Z5>=LOOKUP(Q5,MinHr_Weekly_Bonus!A:A,MinHr_Weekly_Bonus!B:B), LOOKUP(Q5,MinHr_Weekly_Bonus!A:A,MinHr_Weekly_Bonus!C:C), 0)) -> 0 | AB5: =T5+X5 -> 104 | AC5: =IF(AND(U5<1, V5>100, U5>0),"REVIEW: very high KPH","")
A6: Washington | B6: 46036 | C6: Aisha Johnson | D6: Canvasser | E6: Campaign A | F6: Door | G6: No Field Time | I6: 0.39583333 | J6: 0.57638889 | K6: 0 | O6: 0 | P6: 0 | Q6: =B6+MOD(6-WEEKDAY(B6,1),7) -> 46038 | R6: =IF(OR(I6="", J6=""),0,(J6-I6)*24-K6/60) -> 4.3333333 | S6: =IFERROR(__xludf.DUMMYFUNCTION("IFERROR( INDEX( FILTER( Reference!$F:$F, Reference!$A:$A = $E6, Reference!$E:$E = $D6, Reference!$C:$C = $Q6),1),""RATE_NOT_FOUND"")"),24.0) -> 24 | T6: =IF($S6="","", S6*R6) -> 104 | U6: =IF(OR(M6="",L6=""),0,(M6-L6)*24-N6/60) -> 0 | V6: =IF(OR(P6=0, G6="No Field Time"),0,P6/U6) -> 0 | W6: =TEXT(B6,"dddd") -> Wednesday | X6: =IF(AND(OR(W6="Friday", W6="Saturday"), V6>=18), 50, 0) -> 0 | Y6: =IFERROR(__xludf.DUMMYFUNCTION("IFERROR( INDEX( FILTER(Reference!$D:$D, Reference!$A:$A=$E6, Reference!$C:$C=$Q6), 1),"""")"),46038.0) -> 46038 | Z6: =SUMIFS( $U:$U, $C:$C, $C6, $Q:$Q, $Q6 ) -> 9.75 | AA6: =IF(Z6=0,0, IF(Z6>=LOOKUP(Q6,MinHr_Weekly_Bonus!A:A,MinHr_Weekly_Bonus!B:B), LOOKUP(Q6,MinHr_Weekly_Bonus!A:A,MinHr_Weekly_Bonus!C:C), 0)) -> 0 | AB6: =T6+X6 -> 104 | AC6: =IF(AND(U6<1, V6>100, U6>0),"REVIEW: very high KPH","")
A7: Washington | B7: 46036 | C7: Daniel Kim | D7: Canvasser | E7: Campaign A | F7: Door | G7: No Field Time | I7: 0.39583333 | J7: 0.57638889 | K7: 0 | O7: 0 | P7: 0 | Q7: =B7+MOD(6-WEEKDAY(B7,1),7) -> 46038 | R7: =IF(OR(I7="", J7=""),0,(J7-I7)*24-K7/60) -> 4.3333333 | S7: =IFERROR(__xludf.DUMMYFUNCTION("IFERROR( INDEX( FILTER( Reference!$F:$F, Reference!$A:$A = $E7, Reference!$E:$E = $D7, Reference!$C:$C = $Q7),1),""RATE_NOT_FOUND"")"),24.0) -> 24 | T7: =IF($S7="","", S7*R7) -> 104 | U7: =IF(OR(M7="",L7=""),0,(M7-L7)*24-N7/60) -> 0 | V7: =IF(OR(P7=0, G7="No Field Time"),0,P7/U7) -> 0 | W7: =TEXT(B7,"dddd") -> Wednesday | X7: =IF(AND(OR(W7="Friday", W7="Saturday"), V7>=18), 50, 0) -> 0 | Y7: =IFERROR(__xludf.DUMMYFUNCTION("IFERROR( INDEX( FILTER(Reference!$D:$D, Reference!$A:$A=$E7, Reference!$C:$C=$Q7), 1),"""")"),46038.0) -> 46038 | Z7: =SUMIFS( $U:$U, $C:$C, $C7, $Q:$Q, $Q7 ) -> 4.9166667 | AA7: =IF(Z7=0,0, IF(Z7>=LOOKUP(Q7,MinHr_Weekly_Bonus!A:A,MinHr_Weekly_Bonus!B:B), LOOKUP(Q7,MinHr_Weekly_Bonus!A:A,MinHr_Weekly_Bonus!C:C), 0)) -> 0 | AB7: =T7+X7 -> 104 | AC7: =IF(AND(U7<1, V7>100, U7>0),"REVIEW: very high KPH","")
A8: Washington | B8: 46037 | C8: Daniel Kim | D8: Team Lead | E8: Campaign A | F8: Door | G8: Regular | H8: Daniel Kim | I8: 0.44444444 | J8: 0.77430556 | K8: 30 | L8: 0.48958333 | M8: 0.72916667 | N8: 50 | O8: 1 | P8: 94 | Q8: =B8+MOD(6-WEEKDAY(B8,1),7) -> 46038 | R8: =IF(OR(I8="", J8=""),0,(J8-I8)*24-K8/60) -> 7.4166667 | S8: =IFERROR(__xludf.DUMMYFUNCTION("IFERROR( INDEX( FILTER( Reference!$F:$F, Reference!$A:$A = $E8, Reference!$E:$E = $D8, Reference!$C:$C = $Q8),1),""RATE_NOT_FOUND"")"),26.0) -> 26 | T8: =IF($S8="","", S8*R8) -> 192.83333 | U8: =IF(OR(M8="",L8=""),0,(M8-L8)*24-N8/60) -> 4.9166667 | V8: =IF(OR(P8=0, G8="No Field Time"),0,P8/U8) -> 19.118644 | W8: =TEXT(B8,"dddd") -> Thursday | X8: =IF(AND(OR(W8="Friday", W8="Saturday"), V8>=18), 50, 0) -> 0 | Y8: =IFERROR(__xludf.DUMMYFUNCTION("IFERROR( INDEX( FILTER(Reference!$D:$D, Reference!$A:$A=$E8, Reference!$C:$C=$Q8), 1),"""")"),46038.0) -> 46038 | Z8: =SUMIFS( $U:$U, $C:$C, $C8, $Q:$Q, $Q8 ) -> 4.9166667 | AA8: =IF(Z8=0,0, IF(Z8>=LOOKUP(Q8,MinHr_Weekly_Bonus!A:A,MinHr_Weekly_Bonus!B:B), LOOKUP(Q8,MinHr_Weekly_Bonus!A:A,MinHr_Weekly_Bonus!C:C), 0)) -> 0 | AB8: =T8+X8 -> 192.83333 | AC8: =IF(AND(U8<1, V8>100, U8>0),"REVIEW: very high KPH","")
A9: Washington | B9: 46037 | C9: Sofia Martinez | D9: Canvasser | E9: Campaign A | F9: Door | G9: Regular | H9: Daniel Kim | I9: 0.39583333 | J9: 0.76388889 | K9: 30 | L9: 0.48958333 | M9: 0.72916667 | N9: 50 | O9: 1 | P9: 89 | Q9: =B9+MOD(6-WEEKDAY(B9,1),7) -> 46038 | R9: =IF(OR(I9="", J9=""),0,(J9-I9)*24-K9/60) -> 8.3333333 | S9: =IFERROR(__xludf.DUMMYFUNCTION("IFERROR( INDEX( FILTER( Reference!$F:$F, Reference!$A:$A = $E9, Reference!$E:$E = $D9, Reference!$C:$C = $Q9),1),""RATE_NOT_FOUND"")"),24.0) -> 24 | T9: =IF($S9="","", S9*R9) -> 200 | U9: =IF(OR(M9="",L9=""),0,(M9-L9)*24-N9/60) -> 4.9166667 | V9: =IF(OR(P9=0, G9="No Field Time"),0,P9/U9) -> 18.101695 | W9: =TEXT(B9,"dddd") -> Thursday | X9: =IF(AND(OR(W9="Friday", W9="Saturday"), V9>=18), 50, 0) -> 0 | Y9: =IFERROR(__xludf.DUMMYFUNCTION("IFERROR( INDEX( FILTER(Reference!$D:$D, Reference!$A:$A=$E9, Reference!$C:$C=$Q9), 1),"""")"),46038.0) -> 46038 | Z9: =SUMIFS( $U:$U, $C:$C, $C9, $Q:$Q, $Q9 ) -> 9.25 | AA9: =IF(Z9=0,0, IF(Z9>=LOOKUP(Q9,MinHr_Weekly_Bonus!A:A,MinHr_Weekly_Bonus!B:B), LOOKUP(Q9,MinHr_Weekly_Bonus!A:A,MinHr_Weekly_Bonus!C:C), 0)) -> 0 | AB9: =T9+X9 -> 200 | AC9: =IF(AND(U9<1, V9>100, U9>0),"REVIEW: very high KPH","")
A10: Washington | B10: 46037 | C10: Jordan Williams | D10: Canvasser | E10: Campaign A | F10: Door | G10: Regular | H10: Daniel Kim | I10: 0.42708333 | J10: 0.76736111 | K10: 30 | L10: 0.48958333 | M10: 0.72916667 | N10: 50 | O10: 1 | P10: 98 | Q10: =B10+MOD(6-WEEKDAY(B10,1),7) -> 46038 | R10: =IF(OR(I10="", J10=""),0,(J10-I10)*24-K10/60) -> 7.6666667 | S10: =IFERROR(__xludf.DUMMYFUNCTION("IFERROR( INDEX( FILTER( Reference!$F:$F, Reference!$A:$A = $E10, Reference!$E:$E = $D10, Reference!$C:$C = $Q10),1),""RATE_NOT_FOUND"")"),24.0) -> 24 | T10: =IF($S10="","", S10*R10) -> 184 | U10: =IF(OR(M10="",L10=""),0,(M10-L10)*24-N10/60) -> 4.9166667 | V10: =IF(OR(P10=0, G10="No Field Time"),0,P10/U10) -> 19.932203 | W10: =TEXT(B10,"dddd") -> Thursday | X10: =IF(AND(OR(W10="Friday", W10="Saturday"), V10>=18), 50, 0) -> 0 | Y10: =IFERROR(__xludf.DUMMYFUNCTION("IFERROR( INDEX( FILTER(Reference!$D:$D, Reference!$A:$A=$E10, Reference!$C:$C=$Q10), 1),"""")"),46038.0) -> 46038 | Z10: =SUMIFS( $U:$U, $C:$C, $C10, $Q:$Q, $Q10 ) -> 9.8333333 | AA10: =IF(Z10=0,0, IF(Z10>=LOOKUP(Q10,MinHr_Weekly_Bonus!A:A,MinHr_Weekly_Bonus!B:B), LOOKUP(Q10,MinHr_Weekly_Bonus!A:A,MinHr_Weekly_Bonus!C:C), 0)) -> 0 | AB10: =T10+X10 -> 184 | AC10: =IF(AND(U10<1, V10>100, U10>0),"REVIEW: very high KPH","")
A11: Washington | B11: 46037 | C11: Carlos Ramirez | D11: Team Lead | E11: Campaign A | F11: Door | G11: Regular | H11: Carlos Ramirez | I11: 0.44791667 | J11: 0.75902778 | K11: 30 | L11: 0.49305556 | M11: 0.72569444 | N11: 50 | O11: 1 | P11: 64 | Q11: =B11+MOD(6-WEEKDAY(B11,1),7) -> 46038 | R11: =IF(OR(I11="", J11=""),0,(J11-I11)*24-K11/60) -> 6.9666667 | S11: =IFERROR(__xludf.DUMMYFUNCTION("IFERROR( INDEX( FILTER( Reference!$F:$F, Reference!$A:$A = $E11, Reference!$E:$E = $D11, Reference!$C:$C = $Q11),1),""RATE_NOT_FOUND"")"),26.0) -> 26 | T11: =IF($S11="","", S11*R11) -> 181.13333 | U11: =IF(OR(M11="",L11=""),0,(M11-L11)*24-N11/60) -> 4.75 | V11: =IF(OR(P11=0, G11="No Field Time"),0,P11/U11) -> 13.473684 | W11: =TEXT(B11,"dddd") -> Thursday | X11: =IF(AND(OR(W11="Friday", W11="Saturday"), V11>=18), 50, 0) -> 0 | Y11: =IFERROR(__xludf.DUMMYFUNCTION("IFERROR( INDEX( FILTER(Reference!$D:$D, Reference!$A:$A=$E11, Reference!$C:$C=$Q11), 1),"""")"),46038.0) -> 46038 | Z11: =SUMIFS( $U:$U, $C:$C, $C11, $Q:$Q, $Q11 ) -> 9.0833333 | AA11: =IF(Z11=0,0, IF(Z11>=LOOKUP(Q11,MinHr_Weekly_Bonus!A:A,MinHr_Weekly_Bonus!B:B), LOOKUP(Q11,MinHr_Weekly_Bonus!A:A,MinHr_Weekly_Bonus!C:C), 0)) -> 0 | AB11: =T11+X11 -> 181.13333 | AC11: =IF(AND(U11<1, V11>100, U11>0),"REVIEW: very high KPH","")
A12: Washington | B12: 46037 | C12: Marcus Thompson | D12: Canvasser | E12: Campaign A | F12: Door | G12: Regular | H12: Carlos Ramirez | I12: 0.39583333 | J12: 0.77430556 | K12: 30 | L12: 0.48611111 | M12: 0.72916667 | N12: 50 | O12: 1 | P12: 105 | Q12: =B12+MOD(6-WEEKDAY(B12,1),7) -> 46038 | R12: =IF(OR(I12="", J12=""),0,(J12-I12)*24-K12/60) -> 8.5833333 | S12: =IFERROR(__xludf.DUMMYFUNCTION("IFERROR( INDEX( FILTER( Reference!$F:$F, Reference!$A:$A = $E12, Reference!$E:$E = $D12, Reference!$C:$C = $Q12),1),""RATE_NOT_FOUND"")"),24.0) -> 24 | T12: =IF($S12="","", S12*R12) -> 206 | U12: =IF(OR(M12="",L12=""),0,(M12-L12)*24-N12/60) -> 5 | V12: =IF(OR(P12=0, G12="No Field Time"),0,P12/U12) -> 21 | W12: =TEXT(B12,"dddd") -> Thursday | X12: =IF(AND(OR(W12="Friday", W12="Saturday"), V12>=18), 50, 0) -> 0 | Y12: =IFERROR(__xludf.DUMMYFUNCTION("IFERROR( INDEX( FILTER(Reference!$D:$D, Reference!$A:$A=$E12, Reference!$C:$C=$Q12), 1),"""")"),46038.0) -> 46038 | Z12: =SUMIFS( $U:$U, $C:$C, $C12, $Q:$Q, $Q12 ) -> 5 | AA12: =IF(Z12=0,0, IF(Z12>=LOOKUP(Q12,MinHr_Weekly_Bonus!A:A,MinHr_Weekly_Bonus!B:B), LOOKUP(Q12,MinHr_Weekly_Bonus!A:A,MinHr_Weekly_Bonus!C:C), 0)) -> 0 | AB12: =T12+X12 -> 206 | AC12: =IF(AND(U12<1, V12>100, U12>0),"REVIEW: very high KPH","")
A13: Washington | B13: 46037 | C13: Maya Patel | D13: Canvasser | E13: Campaign A | F13: Door | G13: Regular | H13: Carlos Ramirez | I13: 0.42708333 | J13: 0.76875 | K13: 30 | L13: 0.5 | M13: 0.72916667 | N13: 50 | O13: 1 | P13: 75 | Q13: =B13+MOD(6-WEEKDAY(B13,1),7) -> 46038 | R13: =IF(OR(I13="", J13=""),0,(J13-I13)*24-K13/60) -> 7.7 | S13: =IFERROR(__xludf.DUMMYFUNCTION("IFERROR( INDEX( FILTER( Reference!$F:$F, Reference!$A:$A = $E13, Reference!$E:$E = $D13, Reference!$C:$C = $Q13),1),""RATE_NOT_FOUND"")"),24.0) -> 24 | T13: =IF($S13="","", S13*R13) -> 184.8 | U13: =IF(OR(M13="",L13=""),0,(M13-L13)*24-N13/60) -> 4.6666667 | V13: =IF(OR(P13=0, G13="No Field Time"),0,P13/U13) -> 16.071429 | W13: =TEXT(B13,"dddd") -> Thursday | X13: =IF(AND(OR(W13="Friday", W13="Saturday"), V13>=18), 50, 0) -> 0 | Y13: =IFERROR(__xludf.DUMMYFUNCTION("IFERROR( INDEX( FILTER(Reference!$D:$D, Reference!$A:$A=$E13, Reference!$C:$C=$Q13), 1),"""")"),46038.0) -> 46038 | Z13: =SUMIFS( $U:$U, $C:$C, $C13, $Q:$Q, $Q13 ) -> 9.5833333 | AA13: =IF(Z13=0,0, IF(Z13>=LOOKUP(Q13,MinHr_Weekly_Bonus!A:A,MinHr_Weekly_Bonus!B:B), LOOKUP(Q13,MinHr_Weekly_Bonus!A:A,MinHr_Weekly_Bonus!C:C), 0)) -> 0 | AB13: =T13+X13 -> 184.8 | AC13: =IF(AND(U13<1, V13>100, U13>0),"REVIEW: very high KPH","")
A14: Washington | B14: 46037 | C14: Aisha Johnson | D14: Team Lead | E14: Campaign A | F14: Door | G14: Regular | H14: Aisha Johnson | I14: 0.42708333 | J14: 0.75347222 | K14: 30 | L14: 0.5 | M14: 0.72916667 | N14: 50 | O14: 1 | P14: 95 | Q14: =B14+MOD(6-WEEKDAY(B14,1),7) -> 46038 | R14: =IF(OR(I14="", J14=""),0,(J14-I14)*24-K14/60) -> 7.3333333 | S14: =IFERROR(__xludf.DUMMYFUNCTION("IFERROR( INDEX( FILTER( Reference!$F:$F, Reference!$A:$A = $E14, Reference!$E:$E = $D14, Reference!$C:$C = $Q14),1),""RATE_NOT_FOUND"")"),26.0) -> 26 | T14: =IF($S14="","", S14*R14) -> 190.66667 | U14: =IF(OR(M14="",L14=""),0,(M14-L14)*24-N14/60) -> 4.6666667 | V14: =IF(OR(P14=0, G14="No Field Time"),0,P14/U14) -> 20.357143 | W14: =TEXT(B14,"dddd") -> Thursday | X14: =IF(AND(OR(W14="Friday", W14="Saturday"), V14>=18), 50, 0) -> 0 | Y14: =IFERROR(__xludf.DUMMYFUNCTION("IFERROR( INDEX( FILTER(Reference!$D:$D, Reference!$A:$A=$E14, Reference!$C:$C=$Q14), 1),"""")"),46038.0) -> 46038 | Z14: =SUMIFS( $U:$U, $C:$C, $C14, $Q:$Q, $Q14 ) -> 9.75 | AA14: =IF(Z14=0,0, IF(Z14>=LOOKUP(Q14,MinHr_Weekly_Bonus!A:A,MinHr_Weekly_Bonus!B:B), LOOKUP(Q14,MinHr_Weekly_Bonus!A:A,MinHr_Weekly_Bonus!C:C), 0)) -> 0 | AB14: =T14+X14 -> 190.66667 | AC14: =IF(AND(U14<1, V14>100, U14>0),"REVIEW: very high KPH","")
A15: Washington | B15: 46037 | C15: Priya Nair | D15: Canvasser | E15: Campaign A | F15: Door | G15: Regular | H15: Aisha Johnson | I15: 0.39583333 | J15: 0.76041667 | K15: 30 | L15: 0.47916667 | M15: 0.72916667 | N15: 50 | O15: 1 | P15: 55 | Q15: =B15+MOD(6-WEEKDAY(B15,1),7) -> 46038 | R15: =IF(OR(I15="", J15=""),0,(J15-I15)*24-K15/60) -> 8.25 | S15: =IFERROR(__xludf.DUMMYFUNCTION("IFERROR( INDEX( FILTER( Reference!$F:$F, Reference!$A:$A = $E15, Reference!$E:$E = $D15, Reference!$C:$C = $Q15),1),""RATE_NOT_FOUND"")"),24.0) -> 24 | T15: =IF($S15="","", S15*R15) -> 198 | U15: =IF(OR(M15="",L15=""),0,(M15-L15)*24-N15/60) -> 5.1666667 | V15: =IF(OR(P15=0, G15="No Field Time"),0,P15/U15) -> 10.645161 | W15: =TEXT(B15,"dddd") -> Thursday | X15: =IF(AND(OR(W15="Friday", W15="Saturday"), V15>=18), 50, 0) -> 0 | Y15: =IFERROR(__xludf.DUMMYFUNCTION("IFERROR( INDEX( FILTER(Reference!$D:$D, Reference!$A:$A=$E15, Reference!$C:$C=$Q15), 1),"""")"),46038.0) -> 46038 | Z15: =SUMIFS( $U:$U, $C:$C, $C15, $Q:$Q, $Q15 ) -> 10.083333 | AA15: =IF(Z15=0,0, IF(Z15>=LOOKUP(Q15,MinHr_Weekly_Bonus!A:A,MinHr_Weekly_Bonus!B:B), LOOKUP(Q15,MinHr_Weekly_Bonus!A:A,MinHr_Weekly_Bonus!C:C), 0)) -> 0 | AB15: =T15+X15 -> 198 | AC15: =IF(AND(U15<1, V15>100, U15>0),"REVIEW: very high KPH","")
A16: Washington | B16: 46037 | C16: Emily Chen | D16: Canvasser | E16: Campaign A | F16: Door | G16: Regular | H16: Aisha Johnson | I16: 0.42708333 | J16: 0.58333333 | K16: 0 | L16: 0.47916667 | M16: 0.57291667 | N16: 10 | O16: 1 | P16: 96 | Q16: =B16+MOD(6-WEEKDAY(B16,1),7) -> 46038 | R16: =IF(OR(I16="", J16=""),0,(J16-I16)*24-K16/60) -> 3.75 | S16: =IFERROR(__xludf.DUMMYFUNCTION("IFERROR( INDEX( FILTER( Reference!$F:$F, Reference!$A:$A = $E16, Reference!$E:$E = $D16, Reference!$C:$C = $Q16),1),""RATE_NOT_FOUND"")"),24.0) -> 24 | T16: =IF($S16="","", S16*R16) -> 90 | U16: =IF(OR(M16="",L16=""),0,(M16-L16)*24-N16/60) -> 2.0833333 | V16: =IF(OR(P16=0, G16="No Field Time"),0,P16/U16) -> 46.08 | W16: =TEXT(B16,"dddd") -> Thursday | X16: =IF(AND(OR(W16="Friday", W16="Saturday"), V16>=18), 50, 0) -> 0 | Y16: =IFERROR(__xludf.DUMMYFUNCTION("IFERROR( INDEX( FILTER(Reference!$D:$D, Reference!$A:$A=$E16, Reference!$C:$C=$Q16), 1),"""")"),46038.0) -> 46038 | Z16: =SUMIFS( $U:$U, $C:$C, $C16, $Q:$Q, $Q16 ) -> 2.0833333 | AA16: =IF(Z16=0,0, IF(Z16>=LOOKUP(Q16,MinHr_Weekly_Bonus!A:A,MinHr_Weekly_Bonus!B:B), LOOKUP(Q16,MinHr_Weekly_Bonus!A:A,MinHr_Weekly_Bonus!C:C), 0)) -> 0 | AB16: =T16+X16 -> 90 | AC16: =IF(AND(U16<1, V16>100, U16>0),"REVIEW: very high KPH","")
A17: Washington | B17: 46038 | C17: Ethan Brooks | D17: Canvasser | E17: Campaign A | F17: Door | G17: Regular | H17: Aisha Johnson | I17: 0.39583333 | J17: 0.78472222 | K17: 30 | L17: 0.48263889 | M17: 0.72916667 | N17: 50 | O17: 1 | P17: 115 | Q17: =B17+MOD(6-WEEKDAY(B17,1),7) -> 46038 | R17: =IF(OR(I17="", J17=""),0,(J17-I17)*24-K17/60) -> 8.8333333 | S17: =IFERROR(__xludf.DUMMYFUNCTION("IFERROR( INDEX( FILTER( Reference!$F:$F, Reference!$A:$A = $E17, Reference!$E:$E = $D17, Reference!$C:$C = $Q17),1),""RATE_NOT_FOUND"")"),24.0) -> 24 | T17: =IF($S17="","", S17*R17) -> 212 | U17: =IF(OR(M17="",L17=""),0,(M17-L17)*24-N17/60) -> 5.0833333 | V17: =IF(OR(P17=0, G17="No Field Time"),0,P17/U17) -> 22.622951 | W17: =TEXT(B17,"dddd") -> Friday | X17: =IF(AND(OR(W17="Friday", W17="Saturday"), V17>=18), 50, 0) -> 50 | Y17: =IFERROR(__xludf.DUMMYFUNCTION("IFERROR( INDEX( FILTER(Reference!$D:$D, Reference!$A:$A=$E17, Reference!$C:$C=$Q17), 1),"""")"),46038.0) -> 46038 | Z17: =SUMIFS( $U:$U, $C:$C, $C17, $Q:$Q, $Q17 ) -> 5.0833333 | AA17: =IF(Z17=0,0, IF(Z17>=LOOKUP(Q17,MinHr_Weekly_Bonus!A:A,MinHr_Weekly_Bonus!B:B), LOOKUP(Q17,MinHr_Weekly_Bonus!A:A,MinHr_Weekly_Bonus!C:C), 0)) -> 0 | AB17: =T17+X17 -> 262 | AC17: =IF(AND(U17<1, V17>100, U17>0),"REVIEW: very high KPH","")
A18: Washington | B18: 46038 | C18: Aisha Johnson | D18: Team Lead | E18: Campaign A | F18: Door | G18: Regular | H18: Aisha Johnson | I18: 0.42708333 | J18: 0.77986111 | K18: 30 | L18: 0.48263889 | M18: 0.72916667 | N18: 50 | O18: 1 | P18: 60 | Q18: =B18+MOD(6-WEEKDAY(B18,1),7) -> 46038 | R18: =IF(OR(I18="", J18=""),0,(J18-I18)*24-K18/60) -> 7.9666667 | S18: =IFERROR(__xludf.DUMMYFUNCTION("IFERROR( INDEX( FILTER( Reference!$F:$F, Reference!$A:$A = $E18, Reference!$E:$E = $D18, Reference!$C:$C = $Q18),1),""RATE_NOT_FOUND"")"),26.0) -> 26 | T18: =IF($S18="","", S18*R18) -> 207.13333 | U18: =IF(OR(M18="",L18=""),0,(M18-L18)*24-N18/60) -> 5.0833333 | V18: =IF(OR(P18=0, G18="No Field Time"),0,P18/U18) -> 11.803279 | W18: =TEXT(B18,"dddd") -> Friday | X18: =IF(AND(OR(W18="Friday", W18="Saturday"), V18>=18), 50, 0) -> 0 | Y18: =IFERROR(__xludf.DUMMYFUNCTION("IFERROR( INDEX( FILTER(Reference!$D:$D, Reference!$A:$A=$E18, Reference!$C:$C=$Q18), 1),"""")"),46038.0) -> 46038 | Z18: =SUMIFS( $U:$U, $C:$C, $C18, $Q:$Q, $Q18 ) -> 9.75 | AA18: =IF(Z18=0,0, IF(Z18>=LOOKUP(Q18,MinHr_Weekly_Bonus!A:A,MinHr_Weekly_Bonus!B:B), LOOKUP(Q18,MinHr_Weekly_Bonus!A:A,MinHr_Weekly_Bonus!C:C), 0)) -> 0 | AB18: =T18+X18 -> 207.13333 | AC18: =IF(AND(U18<1, V18>100, U18>0),"REVIEW: very high KPH","")
A19: Washington | B19: 46038 | C19: Fatima Hassan | D19: Canvasser | E19: Campaign A | F19: Door | G19: Regular | H19: Aisha Johnson | I19: 0.44791667 | J19: 0.77083333 | K19: 30 | L19: 0.48958333 | M19: 0.72916667 | N19: 50 | O19: 1 | P19: 113 | Q19: =B19+MOD(6-WEEKDAY(B19,1),7) -> 46038 | R19: =IF(OR(I19="", J19=""),0,(J19-I19)*24-K19/60) -> 7.25 | S19: =IFERROR(__xludf.DUMMYFUNCTION("IFERROR( INDEX( FILTER( Reference!$F:$F, Reference!$A:$A = $E19, Reference!$E:$E = $D19, Reference!$C:$C = $Q19),1),""RATE_NOT_FOUND"")"),24.0) -> 24 | T19: =IF($S19="","", S19*R19) -> 174 | U19: =IF(OR(M19="",L19=""),0,(M19-L19)*24-N19/60) -> 4.9166667 | V19: =IF(OR(P19=0, G19="No Field Time"),0,P19/U19) -> 22.983051 | W19: =TEXT(B19,"dddd") -> Friday | X19: =IF(AND(OR(W19="Friday", W19="Saturday"), V19>=18), 50, 0) -> 50 | Y19: =IFERROR(__xludf.DUMMYFUNCTION("IFERROR( INDEX( FILTER(Reference!$D:$D, Reference!$A:$A=$E19, Reference!$C:$C=$Q19), 1),"""")"),46038.0) -> 46038 | Z19: =SUMIFS( $U:$U, $C:$C, $C19, $Q:$Q, $Q19 ) -> 4.9166667 | AA19: =IF(Z19=0,0, IF(Z19>=LOOKUP(Q19,MinHr_Weekly_Bonus!A:A,MinHr_Weekly_Bonus!B:B), LOOKUP(Q19,MinHr_Weekly_Bonus!A:A,MinHr_Weekly_Bonus!C:C), 0)) -> 0 | AB19: =T19+X19 -> 224 | AC19: =IF(AND(U19<1, V19>100, U19>0),"REVIEW: very high KPH","")
A20: Washington | B20: 46038 | C20: Jordan Williams | D20: Canvasser | E20: Campaign A | F20: Door | G20: Regular | H20: Aisha Johnson | I20: 0.44444444 | J20: 0.77083333 | K20: 30 | L20: 0.48958333 | M20: 0.72916667 | N20: 50 | O20: 1 | P20: 67 | Q20: =B20+MOD(6-WEEKDAY(B20,1),7) -> 46038 | R20: =IF(OR(I20="", J20=""),0,(J20-I20)*24-K20/60) -> 7.3333333 | S20: =IFERROR(__xludf.DUMMYFUNCTION("IFERROR( INDEX( FILTER( Reference!$F:$F, Reference!$A:$A = $E20, Reference!$E:$E = $D20, Reference!$C:$C = $Q20),1),""RATE_NOT_FOUND"")"),24.0) -> 24 | T20: =IF($S20="","", S20*R20) -> 176 | U20: =IF(OR(M20="",L20=""),0,(M20-L20)*24-N20/60) -> 4.9166667 | V20: =IF(OR(P20=0, G20="No Field Time"),0,P20/U20) -> 13.627119 | W20: =TEXT(B20,"dddd") -> Friday | X20: =IF(AND(OR(W20="Friday", W20="Saturday"), V20>=18), 50, 0) -> 0 | Y20: =IFERROR(__xludf.DUMMYFUNCTION("IFERROR( INDEX( FILTER(Reference!$D:$D, Reference!$A:$A=$E20, Reference!$C:$C=$Q20), 1),"""")"),46038.0) -> 46038 | Z20: =SUMIFS( $U:$U, $C:$C, $C20, $Q:$Q, $Q20 ) -> 9.8333333 | AA20: =IF(Z20=0,0, IF(Z20>=LOOKUP(Q20,MinHr_Weekly_Bonus!A:A,MinHr_Weekly_Bonus!B:B), LOOKUP(Q20,MinHr_Weekly_Bonus!A:A,MinHr_Weekly_Bonus!C:C), 0)) -> 0 | AB20: =T20+X20 -> 176 | AC20: =IF(AND(U20<1, V20>100, U20>0),"REVIEW: very high KPH","")
A21: Washington | B21: 46038 | C21: Noah Levine | D21: Canvasser | E21: Campaign A | F21: Door | G21: Regular | H21: Aisha Johnson | I21: 0.39583333 | J21: 0.78194444 | K21: 30 | L21: 0.48958333 | M21: 0.72916667 | N21: 50 | O21: 1 | P21: 78 | Q21: =B21+MOD(6-WEEKDAY(B21,1),7) -> 46038 | R21: =IF(OR(I21="", J21=""),0,(J21-I21)*24-K21/60) -> 8.7666667 | S21: =IFERROR(__xludf.DUMMYFUNCTION("IFERROR( INDEX( FILTER( Reference!$F:$F, Reference!$A:$A = $E21, Reference!$E:$E = $D21, Reference!$C:$C = $Q21),1),""RATE_NOT_FOUND"")"),24.0) -> 24 | T21: =IF($S21="","", S21*R21) -> 210.4 | U21: =IF(OR(M21="",L21=""),0,(M21-L21)*24-N21/60) -> 4.9166667 | V21: =IF(OR(P21=0, G21="No Field Time"),0,P21/U21) -> 15.864407 | W21: =TEXT(B21,"dddd") -> Friday | X21: =IF(AND(OR(W21="Friday", W21="Saturday"), V21>=18), 50, 0) -> 0 | Y21: =IFERROR(__xludf.DUMMYFUNCTION("IFERROR( INDEX( FILTER(Reference!$D:$D, Reference!$A:$A=$E21, Reference!$C:$C=$Q21), 1),"""")"),46038.0) -> 46038 | Z21: =SUMIFS( $U:$U, $C:$C, $C21, $Q:$Q, $Q21 ) -> 4.9166667 | AA21: =IF(Z21=0,0, IF(Z21>=LOOKUP(Q21,MinHr_Weekly_Bonus!A:A,MinHr_Weekly_Bonus!B:B), LOOKUP(Q21,MinHr_Weekly_Bonus!A:A,MinHr_Weekly_Bonus!C:C), 0)) -> 0 | AB21: =T21+X21 -> 210.4 | AC21: =IF(AND(U21<1, V21>100, U21>0),"REVIEW: very high KPH","")
A22: Washington | B22: 46038 | C22: Priya Nair | D22: Canvasser | E22: Campaign A | F22: Door | G22: Regular | H22: Grace Nguyen | I22: 0.44444444 | J22: 0.78125 | K22: 30 | L22: 0.48958333 | M22: 0.72916667 | N22: 50 | O22: 1 | P22: 52 | Q22: =B22+MOD(6-WEEKDAY(B22,1),7) -> 46038 | R22: =IF(OR(I22="", J22=""),0,(J22-I22)*24-K22/60) -> 7.5833333 | S22: =IFERROR(__xludf.DUMMYFUNCTION("IFERROR( INDEX( FILTER( Reference!$F:$F, Reference!$A:$A = $E22, Reference!$E:$E = $D22, Reference!$C:$C = $Q22),1),""RATE_NOT_FOUND"")"),24.0) -> 24 | T22: =IF($S22="","", S22*R22) -> 182 | U22: =IF(OR(M22="",L22=""),0,(M22-L22)*24-N22/60) -> 4.9166667 | V22: =IF(OR(P22=0, G22="No Field Time"),0,P22/U22) -> 10.576271 | W22: =TEXT(B22,"dddd") -> Friday | X22: =IF(AND(OR(W22="Friday", W22="Saturday"), V22>=18), 50, 0) -> 0 | Y22: =IFERROR(__xludf.DUMMYFUNCTION("IFERROR( INDEX( FILTER(Reference!$D:$D, Reference!$A:$A=$E22, Reference!$C:$C=$Q22), 1),"""")"),46038.0) -> 46038 | Z22: =SUMIFS( $U:$U, $C:$C, $C22, $Q:$Q, $Q22 ) -> 10.083333 | AA22: =IF(Z22=0,0, IF(Z22>=LOOKUP(Q22,MinHr_Weekly_Bonus!A:A,MinHr_Weekly_Bonus!B:B), LOOKUP(Q22,MinHr_Weekly_Bonus!A:A,MinHr_Weekly_Bonus!C:C), 0)) -> 0 | AB22: =T22+X22 -> 182 | AC22: =IF(AND(U22<1, V22>100, U22>0),"REVIEW: very high KPH","")
A23: Washington | B23: 46038 | C23: Grace Nguyen | D23: Team Lead | E23: Campaign A | F23: Door | G23: Regular | H23: Grace Nguyen | I23: 0.39583333 | J23: 0.77083333 | K23: 30 | L23: 0.48819444 | M23: 0.72916667 | N23: 50 | O23: 1 | P23: 56 | Q23: =B23+MOD(6-WEEKDAY(B23,1),7) -> 46038 | R23: =IF(OR(I23="", J23=""),0,(J23-I23)*24-K23/60) -> 8.5 | S23: =IFERROR(__xludf.DUMMYFUNCTION("IFERROR( INDEX( FILTER( Reference!$F:$F, Reference!$A:$A = $E23, Reference!$E:$E = $D23, Reference!$C:$C = $Q23),1),""RATE_NOT_FOUND"")"),26.0) -> 26 | T23: =IF($S23="","", S23*R23) -> 221 | U23: =IF(OR(M23="",L23=""),0,(M23-L23)*24-N23/60) -> 4.95 | V23: =IF(OR(P23=0, G23="No Field Time"),0,P23/U23) -> 11.313131 | W23: =TEXT(B23,"dddd") -> Friday | X23: =IF(AND(OR(W23="Friday", W23="Saturday"), V23>=18), 50, 0) -> 0 | Y23: =IFERROR(__xludf.DUMMYFUNCTION("IFERROR( INDEX( FILTER(Reference!$D:$D, Reference!$A:$A=$E23, Reference!$C:$C=$Q23), 1),"""")"),46038.0) -> 46038 | Z23: =SUMIFS( $U:$U, $C:$C, $C23, $Q:$Q, $Q23 ) -> 4.95 | AA23: =IF(Z23=0,0, IF(Z23>=LOOKUP(Q23,MinHr_Weekly_Bonus!A:A,MinHr_Weekly_Bonus!B:B), LOOKUP(Q23,MinHr_Weekly_Bonus!A:A,MinHr_Weekly_Bonus!C:C), 0)) -> 0 | AB23: =T23+X23 -> 221 | AC23: =IF(AND(U23<1, V23>100, U23>0),"REVIEW: very high KPH","")
A24: Washington | B24: 46038 | C24: Maya Patel | D24: Canvasser | E24: Campaign A | F24: Door | G24: Regular | H24: Grace Nguyen | I24: 0.44444444 | J24: 0.78055556 | K24: 30 | L24: 0.48958333 | M24: 0.72916667 | N24: 50 | O24: 1 | P24: 89 | Q24: =B24+MOD(6-WEEKDAY(B24,1),7) -> 46038 | R24: =IF(OR(I24="", J24=""),0,(J24-I24)*24-K24/60) -> 7.5666667 | S24: =IFERROR(__xludf.DUMMYFUNCTION("IFERROR( INDEX( FILTER( Reference!$F:$F, Reference!$A:$A = $E24, Reference!$E:$E = $D24, Reference!$C:$C = $Q24),1),""RATE_NOT_FOUND"")"),24.0) -> 24 | T24: =IF($S24="","", S24*R24) -> 181.6 | U24: =IF(OR(M24="",L24=""),0,(M24-L24)*24-N24/60) -> 4.9166667 | V24: =IF(OR(P24=0, G24="No Field Time"),0,P24/U24) -> 18.101695 | W24: =TEXT(B24,"dddd") -> Friday | X24: =IF(AND(OR(W24="Friday", W24="Saturday"), V24>=18), 50, 0) -> 50 | Y24: =IFERROR(__xludf.DUMMYFUNCTION("IFERROR( INDEX( FILTER(Reference!$D:$D, Reference!$A:$A=$E24, Reference!$C:$C=$Q24), 1),"""")"),46038.0) -> 46038 | Z24: =SUMIFS( $U:$U, $C:$C, $C24, $Q:$Q, $Q24 ) -> 9.5833333 | AA24: =IF(Z24=0,0, IF(Z24>=LOOKUP(Q24,MinHr_Weekly_Bonus!A:A,MinHr_Weekly_Bonus!B:B), LOOKUP(Q24,MinHr_Weekly_Bonus!A:A,MinHr_Weekly_Bonus!C:C), 0)) -> 0 | AB24: =T24+X24 -> 231.6 | AC24: =IF(AND(U24<1, V24>100, U24>0),"REVIEW: very high KPH","")
A25: Washington | B25: 46038 | C25: Alejandro Cruz | D25: Canvasser | E25: Campaign A | F25: Door | G25: Regular | H25: Grace Nguyen | I25: 0.39583333 | J25: 0.78680556 | K25: 30 | L25: 0.50347222 | M25: 0.70833333 | N25: 70 | O25: 1 | P25: 62 | Q25: =B25+MOD(6-WEEKDAY(B25,1),7) -> 46038 | R25: =IF(OR(I25="", J25=""),0,(J25-I25)*24-K25/60) -> 8.8833333 | S25: =IFERROR(__xludf.DUMMYFUNCTION("IFERROR( INDEX( FILTER( Reference!$F:$F, Reference!$A:$A = $E25, Reference!$E:$E = $D25, Reference!$C:$C = $Q25),1),""RATE_NOT_FOUND"")"),24.0) -> 24 | T25: =IF($S25="","", S25*R25) -> 213.2 | U25: =IF(OR(M25="",L25=""),0,(M25-L25)*24-N25/60) -> 3.75 | V25: =IF(OR(P25=0, G25="No Field Time"),0,P25/U25) -> 16.533333 | W25: =TEXT(B25,"dddd") -> Friday | X25: =IF(AND(OR(W25="Friday", W25="Saturday"), V25>=18), 50, 0) -> 0 | Y25: =IFERROR(__xludf.DUMMYFUNCTION("IFERROR( INDEX( FILTER(Reference!$D:$D, Reference!$A:$A=$E25, Reference!$C:$C=$Q25), 1),"""")"),46038.0) -> 46038 | Z25: =SUMIFS( $U:$U, $C:$C, $C25, $Q:$Q, $Q25 ) -> 3.75 | AA25: =IF(Z25=0,0, IF(Z25>=LOOKUP(Q25,MinHr_Weekly_Bonus!A:A,MinHr_Weekly_Bonus!B:B), LOOKUP(Q25,MinHr_Weekly_Bonus!A:A,MinHr_Weekly_Bonus!C:C), 0)) -> 0 | AB25: =T25+X25 -> 213.2 | AC25: =IF(AND(U25<1, V25>100, U25>0),"REVIEW: very high KPH","")
A26: Washington | B26: 46038 | C26: Sofia Martinez | D26: Canvasser | E26: Campaign A | F26: Door | G26: Regular | H26: Grace Nguyen | I26: 0.44791667 | J26: 0.79027778 | K26: 30 | L26: 0.5 | M26: 0.72916667 | N26: 70 | O26: 1 | P26: 84 | Q26: =B26+MOD(6-WEEKDAY(B26,1),7) -> 46038 | R26: =IF(OR(I26="", J26=""),0,(J26-I26)*24-K26/60) -> 7.7166667 | S26: =IFERROR(__xludf.DUMMYFUNCTION("IFERROR( INDEX( FILTER( Reference!$F:$F, Reference!$A:$A = $E26, Reference!$E:$E = $D26, Reference!$C:$C = $Q26),1),""RATE_NOT_FOUND"")"),24.0) -> 24 | T26: =IF($S26="","", S26*R26) -> 185.2 | U26: =IF(OR(M26="",L26=""),0,(M26-L26)*24-N26/60) -> 4.3333333 | V26: =IF(OR(P26=0, G26="No Field Time"),0,P26/U26) -> 19.384615 | W26: =TEXT(B26,"dddd") -> Friday | X26: =IF(AND(OR(W26="Friday", W26="Saturday"), V26>=18), 50, 0) -> 50 | Y26: =IFERROR(__xludf.DUMMYFUNCTION("IFERROR( INDEX( FILTER(Reference!$D:$D, Reference!$A:$A=$E26, Reference!$C:$C=$Q26), 1),"""")"),46038.0) -> 46038 | Z26: =SUMIFS( $U:$U, $C:$C, $C26, $Q:$Q, $Q26 ) -> 9.25 | AA26: =IF(Z26=0,0, IF(Z26>=LOOKUP(Q26,MinHr_Weekly_Bonus!A:A,MinHr_Weekly_Bonus!B:B), LOOKUP(Q26,MinHr_Weekly_Bonus!A:A,MinHr_Weekly_Bonus!C:C), 0)) -> 0 | AB26: =T26+X26 -> 235.2 | AC26: =IF(AND(U26<1, V26>100, U26>0),"REVIEW: very high KPH","")
A27: Washington | B27: 46038 | C27: Carlos Ramirez | D27: Canvasser | E27: Campaign A | F27: Door | G27: Regular | H27: Grace Nguyen | I27: 0.47083333 | J27: 0.79166667 | K27: 30 | L27: 0.5 | M27: 0.72916667 | N27: 70 | O27: 1 | P27: 66 | Q27: =B27+MOD(6-WEEKDAY(B27,1),7) -> 46038 | R27: =IF(OR(I27="", J27=""),0,(J27-I27)*24-K27/60) -> 7.2 | S27: =IFERROR(__xludf.DUMMYFUNCTION("IFERROR( INDEX( FILTER( Reference!$F:$F, Reference!$A:$A = $E27, Reference!$E:$E = $D27, Reference!$C:$C = $Q27),1),""RATE_NOT_FOUND"")"),24.0) -> 24 | T27: =IF($S27="","", S27*R27) -> 172.8 | U27: =IF(OR(M27="",L27=""),0,(M27-L27)*24-N27/60) -> 4.3333333 | V27: =IF(OR(P27=0, G27="No Field Time"),0,P27/U27) -> 15.230769 | W27: =TEXT(B27,"dddd") -> Friday | X27: =IF(AND(OR(W27="Friday", W27="Saturday"), V27>=18), 50, 0) -> 0 | Y27: =IFERROR(__xludf.DUMMYFUNCTION("IFERROR( INDEX( FILTER(Reference!$D:$D, Reference!$A:$A=$E27, Reference!$C:$C=$Q27), 1),"""")"),46038.0) -> 46038 | Z27: =SUMIFS( $U:$U, $C:$C, $C27, $Q:$Q, $Q27 ) -> 9.0833333 | AA27: =IF(Z27=0,0, IF(Z27>=LOOKUP(Q27,MinHr_Weekly_Bonus!A:A,MinHr_Weekly_Bonus!B:B), LOOKUP(Q27,MinHr_Weekly_Bonus!A:A,MinHr_Weekly_Bonus!C:C), 0)) -> 0 | AB27: =T27+X27 -> 172.8 | AC27: =IF(AND(U27<1, V27>100, U27>0),"REVIEW: very high KPH","")
A28: Washington | B28: 46039 | C28: Aisha Johnson | D28: Team Lead | E28: Campaign A | F28: Door | G28: Regular | H28: Aisha Johnson | I28: 0.42361111 | J28: 0.78194444 | K28: 30 | L28: 0.47569444 | M28: 0.72916667 | N28: 90 | O28: 1 | P28: 80 | Q28: =B28+MOD(6-WEEKDAY(B28,1),7) -> 46045 | R28: =IF(OR(I28="", J28=""),0,(J28-I28)*24-K28/60) -> 8.1 | S28: =IFERROR(__xludf.DUMMYFUNCTION("IFERROR( INDEX( FILTER( Reference!$F:$F, Reference!$A:$A = $E28, Reference!$E:$E = $D28, Reference!$C:$C = $Q28),1),""RATE_NOT_FOUND"")"),26.0) -> 26 | T28: =IF($S28="","", S28*R28) -> 210.6 | U28: =IF(OR(M28="",L28=""),0,(M28-L28)*24-N28/60) -> 4.5833333 | V28: =IF(OR(P28=0, G28="No Field Time"),0,P28/U28) -> 17.454545 | W28: =TEXT(B28,"dddd") -> Saturday | X28: =IF(AND(OR(W28="Friday", W28="Saturday"), V28>=18), 50, 0) -> 0 | Y28: =IFERROR(__xludf.DUMMYFUNCTION("IFERROR( INDEX( FILTER(Reference!$D:$D, Reference!$A:$A=$E28, Reference!$C:$C=$Q28), 1),"""")"),46052.0) -> 46052 | Z28: =SUMIFS( $U:$U, $C:$C, $C28, $Q:$Q, $Q28 ) -> 23.833333 | AA28: =IF(Z28=0,0, IF(Z28>=LOOKUP(Q28,MinHr_Weekly_Bonus!A:A,MinHr_Weekly_Bonus!B:B), LOOKUP(Q28,MinHr_Weekly_Bonus!A:A,MinHr_Weekly_Bonus!C:C), 0)) -> 100 | AB28: =T28+X28 -> 210.6 | AC28: =IF(AND(U28<1, V28>100, U28>0),"REVIEW: very high KPH","")
A29: Washington | B29: 46039 | C29: Hannah O’Connor | D29: Canvasser | E29: Campaign A | F29: Door | G29: Regular | H29: Aisha Johnson | I29: 0.39583333 | J29: 0.76041667 | K29: 30 | L29: 0.47569444 | M29: 0.72916667 | N29: 90 | O29: 1 | P29: 105 | Q29: =B29+MOD(6-WEEKDAY(B29,1),7) -> 46045 | R29: =IF(OR(I29="", J29=""),0,(J29-I29)*24-K29/60) -> 8.25 | S29: =IFERROR(__xludf.DUMMYFUNCTION("IFERROR( INDEX( FILTER( Reference!$F:$F, Reference!$A:$A = $E29, Reference!$E:$E = $D29, Reference!$C:$C = $Q29),1),""RATE_NOT_FOUND"")"),24.0) -> 24 | T29: =IF($S29="","", S29*R29) -> 198 | U29: =IF(OR(M29="",L29=""),0,(M29-L29)*24-N29/60) -> 4.5833333 | V29: =IF(OR(P29=0, G29="No Field Time"),0,P29/U29) -> 22.909091 | W29: =TEXT(B29,"dddd") -> Saturday | X29: =IF(AND(OR(W29="Friday", W29="Saturday"), V29>=18), 50, 0) -> 50 | Y29: =IFERROR(__xludf.DUMMYFUNCTION("IFERROR( INDEX( FILTER(Reference!$D:$D, Reference!$A:$A=$E29, Reference!$C:$C=$Q29), 1),"""")"),46052.0) -> 46052 | Z29: =SUMIFS( $U:$U, $C:$C, $C29, $Q:$Q, $Q29 ) -> 9.4166667 | AA29: =IF(Z29=0,0, IF(Z29>=LOOKUP(Q29,MinHr_Weekly_Bonus!A:A,MinHr_Weekly_Bonus!B:B), LOOKUP(Q29,MinHr_Weekly_Bonus!A:A,MinHr_Weekly_Bonus!C:C), 0)) -> 0 | AB29: =T29+X29 -> 248 | AC29: =IF(AND(U29<1, V29>100, U29>0),"REVIEW: very high KPH","")
A30: Washington | B30: 46039 | C30: Jamal Washington | D30: Canvasser | E30: Campaign A | F30: Door | G30: Regular | H30: Aisha Johnson | I30: 0.39583333 | J30: 0.77777778 | K30: 30 | L30: 0.47569444 | M30: 0.72916667 | N30: 90 | O30: 1 | P30: 82 | Q30: =B30+MOD(6-WEEKDAY(B30,1),7) -> 46045 | R30: =IF(OR(I30="", J30=""),0,(J30-I30)*24-K30/60) -> 8.6666667 | S30: =IFERROR(__xludf.DUMMYFUNCTION("IFERROR( INDEX( FILTER( Reference!$F:$F, Reference!$A:$A = $E30, Reference!$E:$E = $D30, Reference!$C:$C = $Q30),1),""RATE_NOT_FOUND"")"),24.0) -> 24 | T30: =IF($S30="","", S30*R30) -> 208 | U30: =IF(OR(M30="",L30=""),0,(M30-L30)*24-N30/60) -> 4.5833333 | V30: =IF(OR(P30=0, G30="No Field Time"),0,P30/U30) -> 17.890909 | W30: =TEXT(B30,"dddd") -> Saturday | X30: =IF(AND(OR(W30="Friday", W30="Saturday"), V30>=18), 50, 0) -> 0 | Y30: =IFERROR(__xludf.DUMMYFUNCTION("IFERROR( INDEX( FILTER(Reference!$D:$D, Reference!$A:$A=$E30, Reference!$C:$C=$Q30), 1),"""")"),46052.0) -> 46052 | Z30: =SUMIFS( $U:$U, $C:$C, $C30, $Q:$Q, $Q30 ) -> 9.5833333 | AA30: =IF(Z30=0,0, IF(Z30>=LOOKUP(Q30,MinHr_Weekly_Bonus!A:A,MinHr_Weekly_Bonus!B:B), LOOKUP(Q30,MinHr_Weekly_Bonus!A:A,MinHr_Weekly_Bonus!C:C), 0)) -> 0 | AB30: =T30+X30 -> 208 | AC30: =IF(AND(U30<1, V30>100, U30>0),"REVIEW: very high KPH","")
A31: Washington | B31: 46039 | C31: Linh Tran | D31: Canvasser | E31: Campaign A | F31: Door | G31: Regular | H31: Aisha Johnson | I31: 0.39583333 | J31: 0.75694444 | K31: 30 | L31: 0.47569444 | M31: 0.72916667 | N31: 90 | O31: 1 | P31: 109 | Q31: =B31+MOD(6-WEEKDAY(B31,1),7) -> 46045 | R31: =IF(OR(I31="", J31=""),0,(J31-I31)*24-K31/60) -> 8.1666667 | S31: =IFERROR(__xludf.DUMMYFUNCTION("IFERROR( INDEX( FILTER( Reference!$F:$F, Reference!$A:$A = $E31, Reference!$E:$E = $D31, Reference!$C:$C = $Q31),1),""RATE_NOT_FOUND"")"),24.0) -> 24 | T31: =IF($S31="","", S31*R31) -> 196 | U31: =IF(OR(M31="",L31=""),0,(M31-L31)*24-N31/60) -> 4.5833333 | V31: =IF(OR(P31=0, G31="No Field Time"),0,P31/U31) -> 23.781818 | W31: =TEXT(B31,"dddd") -> Saturday | X31: =IF(AND(OR(W31="Friday", W31="Saturday"), V31>=18), 50, 0) -> 50 | Y31: =IFERROR(__xludf.DUMMYFUNCTION("IFERROR( INDEX( FILTER(Reference!$D:$D, Reference!$A:$A=$E31, Reference!$C:$C=$Q31), 1),"""")"),46052.0) -> 46052 | Z31: =SUMIFS( $U:$U, $C:$C, $C31, $Q:$Q, $Q31 ) -> 4.5833333 | AA31: =IF(Z31=0,0, IF(Z31>=LOOKUP(Q31,MinHr_Weekly_Bonus!A:A,MinHr_Weekly_Bonus!B:B), LOOKUP(Q31,MinHr_Weekly_Bonus!A:A,MinHr_Weekly_Bonus!C:C), 0)) -> 0 | AB31: =T31+X31 -> 246 | AC31: =IF(AND(U31<1, V31>100, U31>0),"REVIEW: very high KPH","")
A32: Washington | B32: 46039 | C32: Olivia Bennett | D32: Canvasser | E32: Campaign A | F32: Door | G32: Regular | H32: Aisha Johnson | I32: 0.39583333 | J32: 0.76388889 | K32: 30 | L32: 0.49097222 | M32: 0.72916667 | N32: 50 | O32: 1 | P32: 111 | Q32: =B32+MOD(6-WEEKDAY(B32,1),7) -> 46045 | R32: =IF(OR(I32="", J32=""),0,(J32-I32)*24-K32/60) -> 8.3333333 | S32: =IFERROR(__xludf.DUMMYFUNCTION("IFERROR( INDEX( FILTER( Reference!$F:$F, Reference!$A:$A = $E32, Reference!$E:$E = $D32, Reference!$C:$C = $Q32),1),""RATE_NOT_FOUND"")"),24.0) -> 24 | T32: =IF($S32="","", S32*R32) -> 200 | U32: =IF(OR(M32="",L32=""),0,(M32-L32)*24-N32/60) -> 4.8833333 | V32: =IF(OR(P32=0, G32="No Field Time"),0,P32/U32) -> 22.730375 | W32: =TEXT(B32,"dddd") -> Saturday | X32: =IF(AND(OR(W32="Friday", W32="Saturday"), V32>=18), 50, 0) -> 50 | Y32: =IFERROR(__xludf.DUMMYFUNCTION("IFERROR( INDEX( FILTER(Reference!$D:$D, Reference!$A:$A=$E32, Reference!$C:$C=$Q32), 1),"""")"),46052.0) -> 46052 | Z32: =SUMIFS( $U:$U, $C:$C, $C32, $Q:$Q, $Q32 ) -> 14.216667 | AA32: =IF(Z32=0,0, IF(Z32>=LOOKUP(Q32,MinHr_Weekly_Bonus!A:A,MinHr_Weekly_Bonus!B:B), LOOKUP(Q32,MinHr_Weekly_Bonus!A:A,MinHr_Weekly_Bonus!C:C), 0)) -> 0 | AB32: =T32+X32 -> 250 | AC32: =IF(AND(U32<1, V32>100, U32>0),"REVIEW: very high KPH","")
A33: Washington | B33: 46039 | C33: Rohan Mehta | D33: Canvasser | E33: Campaign A | F33: Door | G33: Regular | H33: Aisha Johnson | I33: 0.39583333 | J33: 0.76736111 | K33: 30 | L33: 0.49097222 | M33: 0.72916667 | N33: 50 | O33: 1 | P33: 72 | Q33: =B33+MOD(6-WEEKDAY(B33,1),7) -> 46045 | R33: =IF(OR(I33="", J33=""),0,(J33-I33)*24-K33/60) -> 8.4166667 | S33: =IFERROR(__xludf.DUMMYFUNCTION("IFERROR( INDEX( FILTER( Reference!$F:$F, Reference!$A:$A = $E33, Reference!$E:$E = $D33, Reference!$C:$C = $Q33),1),""RATE_NOT_FOUND"")"),24.0) -> 24 | T33: =IF($S33="","", S33*R33) -> 202 | U33: =IF(OR(M33="",L33=""),0,(M33-L33)*24-N33/60) -> 4.8833333 | V33: =IF(OR(P33=0, G33="No Field Time"),0,P33/U33) -> 14.744027 | W33: =TEXT(B33,"dddd") -> Saturday | X33: =IF(AND(OR(W33="Friday", W33="Saturday"), V33>=18), 50, 0) -> 0 | Y33: =IFERROR(__xludf.DUMMYFUNCTION("IFERROR( INDEX( FILTER(Reference!$D:$D, Reference!$A:$A=$E33, Reference!$C:$C=$Q33), 1),"""")"),46052.0) -> 46052 | Z33: =SUMIFS( $U:$U, $C:$C, $C33, $Q:$Q, $Q33 ) -> 15.133333 | AA33: =IF(Z33=0,0, IF(Z33>=LOOKUP(Q33,MinHr_Weekly_Bonus!A:A,MinHr_Weekly_Bonus!B:B), LOOKUP(Q33,MinHr_Weekly_Bonus!A:A,MinHr_Weekly_Bonus!C:C), 0)) -> 0 | AB33: =T33+X33 -> 202 | AC33: =IF(AND(U33<1, V33>100, U33>0),"REVIEW: very high KPH","")
A34: Washington | B34: 46039 | C34: Isabella Flores | D34: Canvasser | E34: Campaign A | F34: Door | G34: Regular | H34: Aisha Johnson | I34: 0.39583333 | J34: 0.77083333 | K34: 30 | L34: 0.47847222 | M34: 0.72916667 | N34: 60 | O34: 1 | P34: 97 | Q34: =B34+MOD(6-WEEKDAY(B34,1),7) -> 46045 | R34: =IF(OR(I34="", J34=""),0,(J34-I34)*24-K34/60) -> 8.5 | S34: =IFERROR(__xludf.DUMMYFUNCTION("IFERROR( INDEX( FILTER( Reference!$F:$F, Reference!$A:$A = $E34, Reference!$E:$E = $D34, Reference!$C:$C = $Q34),1),""RATE_NOT_FOUND"")"),24.0) -> 24 | T34: =IF($S34="","", S34*R34) -> 204 | U34: =IF(OR(M34="",L34=""),0,(M34-L34)*24-N34/60) -> 5.0166667 | V34: =IF(OR(P34=0, G34="No Field Time"),0,P34/U34) -> 19.335548 | W34: =TEXT(B34,"dddd") -> Saturday | X34: =IF(AND(OR(W34="Friday", W34="Saturday"), V34>=18), 50, 0) -> 50 | Y34: =IFERROR(__xludf.DUMMYFUNCTION("IFERROR( INDEX( FILTER(Reference!$D:$D, Reference!$A:$A=$E34, Reference!$C:$C=$Q34), 1),"""")"),46052.0) -> 46052 | Z34: =SUMIFS( $U:$U, $C:$C, $C34, $Q:$Q, $Q34 ) -> 24.716667 | AA34: =IF(Z34=0,0, IF(Z34>=LOOKUP(Q34,MinHr_Weekly_Bonus!A:A,MinHr_Weekly_Bonus!B:B), LOOKUP(Q34,MinHr_Weekly_Bonus!A:A,MinHr_Weekly_Bonus!C:C), 0)) -> 100 | AB34: =T34+X34 -> 254 | AC34: =IF(AND(U34<1, V34>100, U34>0),"REVIEW: very high KPH","")
A35: Washington | B35: 46039 | C35: Maya Patel | D35: Team Lead | E35: Campaign B | F35: Door | G35: Regular | H35: Maya Patel | I35: 0.42361111 | J35: 0.78194444 | K35: 30 | L35: 0.47847222 | M35: 0.72916667 | N35: 75 | O35: 1 | P35: 66 | Q35: =B35+MOD(6-WEEKDAY(B35,1),7) -> 46045 | R35: =IF(OR(I35="", J35=""),0,(J35-I35)*24-K35/60) -> 8.1 | S35: =IFERROR(__xludf.DUMMYFUNCTION("IFERROR( INDEX( FILTER( Reference!$F:$F, Reference!$A:$A = $E35, Reference!$E:$E = $D35, Reference!$C:$C = $Q35),1),""RATE_NOT_FOUND"")"),26.0) -> 26 | T35: =IF($S35="","", S35*R35) -> 210.6 | U35: =IF(OR(M35="",L35=""),0,(M35-L35)*24-N35/60) -> 4.7666667 | V35: =IF(OR(P35=0, G35="No Field Time"),0,P35/U35) -> 13.846154 | W35: =TEXT(B35,"dddd") -> Saturday | X35: =IF(AND(OR(W35="Friday", W35="Saturday"), V35>=18), 50, 0) -> 0 | Y35: =IFERROR(__xludf.DUMMYFUNCTION("IFERROR( INDEX( FILTER(Reference!$D:$D, Reference!$A:$A=$E35, Reference!$C:$C=$Q35), 1),"""")"),46052.0) -> 46052 | Z35: =SUMIFS( $U:$U, $C:$C, $C35, $Q:$Q, $Q35 ) -> 24.433333 | AA35: =IF(Z35=0,0, IF(Z35>=LOOKUP(Q35,MinHr_Weekly_Bonus!A:A,MinHr_Weekly_Bonus!B:B), LOOKUP(Q35,MinHr_Weekly_Bonus!A:A,MinHr_Weekly_Bonus!C:C), 0)) -> 100 | AB35: =T35+X35 -> 210.6 | AC35: =IF(AND(U35<1, V35>100, U35>0),"REVIEW: very high KPH","")
A36: Washington | B36: 46039 | C36: Alejandro Cruz | D36: Canvasser | E36: Campaign B | F36: Door | G36: Regular | H36: Maya Patel | I36: 0.44861111 | J36: 0.78680556 | K36: 30 | L36: 0.47847222 | M36: 0.72916667 | N36: 50 | O36: 1 | P36: 57 | Q36: =B36+MOD(6-WEEKDAY(B36,1),7) -> 46045 | R36: =IF(OR(I36="", J36=""),0,(J36-I36)*24-K36/60) -> 7.6166667 | S36: =IFERROR(__xludf.DUMMYFUNCTION("IFERROR( INDEX( FILTER( Reference!$F:$F, Reference!$A:$A = $E36, Reference!$E:$E = $D36, Reference!$C:$C = $Q36),1),""RATE_NOT_FOUND"")"),24.0) -> 24 | T36: =IF($S36="","", S36*R36) -> 182.8 | U36: =IF(OR(M36="",L36=""),0,(M36-L36)*24-N36/60) -> 5.1833333 | V36: =IF(OR(P36=0, G36="No Field Time"),0,P36/U36) -> 10.996785 | W36: =TEXT(B36,"dddd") -> Saturday | X36: =IF(AND(OR(W36="Friday", W36="Saturday"), V36>=18), 50, 0) -> 0 | Y36: =IFERROR(__xludf.DUMMYFUNCTION("IFERROR( INDEX( FILTER(Reference!$D:$D, Reference!$A:$A=$E36, Reference!$C:$C=$Q36), 1),"""")"),46052.0) -> 46052 | Z36: =SUMIFS( $U:$U, $C:$C, $C36, $Q:$Q, $Q36 ) -> 25.35 | AA36: =IF(Z36=0,0, IF(Z36>=LOOKUP(Q36,MinHr_Weekly_Bonus!A:A,MinHr_Weekly_Bonus!B:B), LOOKUP(Q36,MinHr_Weekly_Bonus!A:A,MinHr_Weekly_Bonus!C:C), 0)) -> 100 | AB36: =T36+X36 -> 182.8 | AC36: =IF(AND(U36<1, V36>100, U36>0),"REVIEW: very high KPH","")
A37: Washington | B37: 46039 | C37: Samuel Wright | D37: Canvasser | E37: Campaign B | F37: Door | G37: Regular | H37: Maya Patel | I37: 0.39583333 | J37: 0.77569444 | K37: 30 | L37: 0.48263889 | M37: 0.72916667 | N37: 50 | O37: 1 | P37: 55 | Q37: =B37+MOD(6-WEEKDAY(B37,1),7) -> 46045 | R37: =IF(OR(I37="", J37=""),0,(J37-I37)*24-K37/60) -> 8.6166667 | S37: =IFERROR(__xludf.DUMMYFUNCTION("IFERROR( INDEX( FILTER( Reference!$F:$F, Reference!$A:$A = $E37, Reference!$E:$E = $D37, Reference!$C:$C = $Q37),1),""RATE_NOT_FOUND"")"),24.0) -> 24 | T37: =IF($S37="","", S37*R37) -> 206.8 | U37: =IF(OR(M37="",L37=""),0,(M37-L37)*24-N37/60) -> 5.0833333 | V37: =IF(OR(P37=0, G37="No Field Time"),0,P37/U37) -> 10.819672 | W37: =TEXT(B37,"dddd") -> Saturday | X37: =IF(AND(OR(W37="Friday", W37="Saturday"), V37>=18), 50, 0) -> 0 | Y37: =IFERROR(__xludf.DUMMYFUNCTION("IFERROR( INDEX( FILTER(Reference!$D:$D, Reference!$A:$A=$E37, Reference!$C:$C=$Q37), 1),"""")"),46052.0) -> 46052 | Z37: =SUMIFS( $U:$U, $C:$C, $C37, $Q:$Q, $Q37 ) -> 19.166667 | AA37: =IF(Z37=0,0, IF(Z37>=LOOKUP(Q37,MinHr_Weekly_Bonus!A:A,MinHr_Weekly_Bonus!B:B), LOOKUP(Q37,MinHr_Weekly_Bonus!A:A,MinHr_Weekly_Bonus!C:C), 0)) -> 0 | AB37: =T37+X37 -> 206.8 | AC37: =IF(AND(U37<1, V37>100, U37>0),"REVIEW: very high KPH","")
A38: Washington | B38: 46039 | C38: Caleb Robinson | D38: Canvasser | E38: Campaign B | F38: Door | G38: Regular | H38: Maya Patel | I38: 0.39583333 | J38: 0.78125 | K38: 30 | L38: 0.48263889 | M38: 0.72916667 | N38: 50 | O38: 1 | P38: 106 | Q38: =B38+MOD(6-WEEKDAY(B38,1),7) -> 46045 | R38: =IF(OR(I38="", J38=""),0,(J38-I38)*24-K38/60) -> 8.75 | S38: =IFERROR(__xludf.DUMMYFUNCTION("IFERROR( INDEX( FILTER( Reference!$F:$F, Reference!$A:$A = $E38, Reference!$E:$E = $D38, Reference!$C:$C = $Q38),1),""RATE_NOT_FOUND"")"),24.0) -> 24 | T38: =IF($S38="","", S38*R38) -> 210 | U38: =IF(OR(M38="",L38=""),0,(M38-L38)*24-N38/60) -> 5.0833333 | V38: =IF(OR(P38=0, G38="No Field Time"),0,P38/U38) -> 20.852459 | W38: =TEXT(B38,"dddd") -> Saturday | X38: =IF(AND(OR(W38="Friday", W38="Saturday"), V38>=18), 50, 0) -> 50 | Y38: =IFERROR(__xludf.DUMMYFUNCTION("IFERROR( INDEX( FILTER(Reference!$D:$D, Reference!$A:$A=$E38, Reference!$C:$C=$Q38), 1),"""")"),46052.0) -> 46052 | Z38: =SUMIFS( $U:$U, $C:$C, $C38, $Q:$Q, $Q38 ) -> 5.0833333 | AA38: =IF(Z38=0,0, IF(Z38>=LOOKUP(Q38,MinHr_Weekly_Bonus!A:A,MinHr_Weekly_Bonus!B:B), LOOKUP(Q38,MinHr_Weekly_Bonus!A:A,MinHr_Weekly_Bonus!C:C), 0)) -> 0 | AB38: =T38+X38 -> 260 | AC38: =IF(AND(U38<1, V38>100, U38>0),"REVIEW: very high KPH","")
A39: Washington | B39: 46039 | C39: Grace Nguyen | D39: Canvasser | E39: Campaign B | F39: Door | G39: Regular | H39: Maya Patel | I39: 0.44583333 | J39: 0.82430556 | K39: 30 | L39: 0.48263889 | M39: 0.72916667 | N39: 50 | O39: 1 | P39: 110 | Q39: =B39+MOD(6-WEEKDAY(B39,1),7) -> 46045 | R39: =IF(OR(I39="", J39=""),0,(J39-I39)*24-K39/60) -> 8.5833333 | S39: =IFERROR(__xludf.DUMMYFUNCTION("IFERROR( INDEX( FILTER( Reference!$F:$F, Reference!$A:$A = $E39, Reference!$E:$E = $D39, Reference!$C:$C = $Q39),1),""RATE_NOT_FOUND"")"),24.0) -> 24 | T39: =IF($S39="","", S39*R39) -> 206 | U39: =IF(OR(M39="",L39=""),0,(M39-L39)*24-N39/60) -> 5.0833333 | V39: =IF(OR(P39=0, G39="No Field Time"),0,P39/U39) -> 21.639344 | W39: =TEXT(B39,"dddd") -> Saturday | X39: =IF(AND(OR(W39="Friday", W39="Saturday"), V39>=18), 50, 0) -> 50 | Y39: =IFERROR(__xludf.DUMMYFUNCTION("IFERROR( INDEX( FILTER(Reference!$D:$D, Reference!$A:$A=$E39, Reference!$C:$C=$Q39), 1),"""")"),46052.0) -> 46052 | Z39: =SUMIFS( $U:$U, $C:$C, $C39, $Q:$Q, $Q39 ) -> 19.366667 | AA39: =IF(Z39=0,0, IF(Z39>=LOOKUP(Q39,MinHr_Weekly_Bonus!A:A,MinHr_Weekly_Bonus!B:B), LOOKUP(Q39,MinHr_Weekly_Bonus!A:A,MinHr_Weekly_Bonus!C:C), 0)) -> 0 | AB39: =T39+X39 -> 256 | AC39: =IF(AND(U39<1, V39>100, U39>0),"REVIEW: very high KPH","")
A40: Washington | B40: 46039 | C40: Sofia Martinez | D40: Canvasser | E40: Campaign B | F40: Door | G40: Regular | H40: Maya Patel | I40: 0.44652778 | J40: 0.79166667 | K40: 30 | L40: 0.48611111 | M40: 0.72916667 | N40: 60 | O40: 1 | P40: 52 | Q40: =B40+MOD(6-WEEKDAY(B40,1),7) -> 46045 | R40: =IF(OR(I40="", J40=""),0,(J40-I40)*24-K40/60) -> 7.7833333 | S40: =IFERROR(__xludf.DUMMYFUNCTION("IFERROR( INDEX( FILTER( Reference!$F:$F, Reference!$A:$A = $E40, Reference!$E:$E = $D40, Reference!$C:$C = $Q40),1),""RATE_NOT_FOUND"")"),24.0) -> 24 | T40: =IF($S40="","", S40*R40) -> 186.8 | U40: =IF(OR(M40="",L40=""),0,(M40-L40)*24-N40/60) -> 4.8333333 | V40: =IF(OR(P40=0, G40="No Field Time"),0,P40/U40) -> 10.758621 | W40: =TEXT(B40,"dddd") -> Saturday | X40: =IF(AND(OR(W40="Friday", W40="Saturday"), V40>=18), 50, 0) -> 0 | Y40: =IFERROR(__xludf.DUMMYFUNCTION("IFERROR( INDEX( FILTER(Reference!$D:$D, Reference!$A:$A=$E40, Reference!$C:$C=$Q40), 1),"""")"),46052.0) -> 46052 | Z40: =SUMIFS( $U:$U, $C:$C, $C40, $Q:$Q, $Q40 ) -> 4.8333333 | AA40: =IF(Z40=0,0, IF(Z40>=LOOKUP(Q40,MinHr_Weekly_Bonus!A:A,MinHr_Weekly_Bonus!B:B), LOOKUP(Q40,MinHr_Weekly_Bonus!A:A,MinHr_Weekly_Bonus!C:C), 0)) -> 0 | AB40: =T40+X40 -> 186.8 | AC40: =IF(AND(U40<1, V40>100, U40>0),"REVIEW: very high KPH","")
...

Sheet MinHr_Weekly_Bonus
A1: Week Ending | B1: Minimum Canvassing Hours | C1: Bonus Amount
A2: 46038 | B2: 22 | C2: 100
A3: 46052 | B3: 25 | C3: 150
A18: Note: Defines weekly bonus rules based on week end date.

Sheet Weekly_Bonus_By_Person
A1: Canvasser | B1: Week End Date Per Shift | C1: Pay Period | D1: Weekly Bonus
A2: =IFERROR(__xludf.DUMMYFUNCTION("UNIQUE( FILTER( { Data!$C$2:$C1000, Data!$Q$2:$Q1000, Data!$Y$2:$Y1000 }, LEN(Data!$C$2:$C1000) ) )"),"Maya Patel") -> Maya Patel | B2: =IFERROR(__xludf.DUMMYFUNCTION("""COMPUTED_VALUE"""),46038.0) -> 46038 | C2: =IFERROR(__xludf.DUMMYFUNCTION("""COMPUTED_VALUE"""),46038.0) -> 46038 | D2: =IFERROR(__xludf.DUMMYFUNCTION("IF( A2="""", """", IFERROR( INDEX( FILTER( Data!$AA:$AA, Data!$C:$C=$A2, Data!$Q:$Q=$B2 ), 1 ), 0 ) )"),0.0) -> 0
A3: =IFERROR(__xludf.DUMMYFUNCTION("""COMPUTED_VALUE"""),"Jordan Williams") -> Jordan Williams | B3: =IFERROR(__xludf.DUMMYFUNCTION("""COMPUTED_VALUE"""),46038.0) -> 46038 | C3: =IFERROR(__xludf.DUMMYFUNCTION("""COMPUTED_VALUE"""),46038.0) -> 46038 | D3: =IFERROR(__xludf.DUMMYFUNCTION("IF( A3="""", """", IFERROR( INDEX( FILTER( Data!$AA:$AA, Data!$C:$C=$A3, Data!$Q:$Q=$B3 ), 1 ), 0 ) )"),0.0) -> 0
A4: =IFERROR(__xludf.DUMMYFUNCTION("""COMPUTED_VALUE"""),"Carlos Ramirez") -> Carlos Ramirez | B4: =IFERROR(__xludf.DUMMYFUNCTION("""COMPUTED_VALUE"""),46038.0) -> 46038 | C4: =IFERROR(__xludf.DUMMYFUNCTION("""COMPUTED_VALUE"""),46038.0) -> 46038 | D4: =IFERROR(__xludf.DUMMYFUNCTION("IF( A4="""", """", IFERROR( INDEX( FILTER( Data!$AA:$AA, Data!$C:$C=$A4, Data!$Q:$Q=$B4 ), 1 ), 0 ) )"),0.0) -> 0
A5: =IFERROR(__xludf.DUMMYFUNCTION("""COMPUTED_VALUE"""),"Emily Chen") -> Emily Chen | B5: =IFERROR(__xludf.DUMMYFUNCTION("""COMPUTED_VALUE"""),46038.0) -> 46038 | C5: =IFERROR(__xludf.DUMMYFUNCTION("""COMPUTED_VALUE"""),46038.0) -> 46038 | D5: =IFERROR(__xludf.DUMMYFUNCTION("IF( A5="""", """", IFERROR( INDEX( FILTER( Data!$AA:$AA, Data!$C:$C=$A5, Data!$Q:$Q=$B5 ), 1 ), 0 ) )"),0.0) -> 0
A6: =IFERROR(__xludf.DUMMYFUNCTION("""COMPUTED_VALUE"""),"Aisha Johnson") -> Aisha Johnson | B6: =IFERROR(__xludf.DUMMYFUNCTION("""COMPUTED_VALUE"""),46038.0) -> 46038 | C6: =IFERROR(__xludf.DUMMYFUNCTION("""COMPUTED_VALUE"""),46038.0) -> 46038 | D6: =IFERROR(__xludf.DUMMYFUNCTION("IF( A6="""", """", IFERROR( INDEX( FILTER( Data!$AA:$AA, Data!$C:$C=$A6, Data!$Q:$Q=$B6 ), 1 ), 0 ) )"),0.0) -> 0
A7: =IFERROR(__xludf.DUMMYFUNCTION("""COMPUTED_VALUE"""),"Daniel Kim") -> Daniel Kim | B7: =IFERROR(__xludf.DUMMYFUNCTION("""COMPUTED_VALUE"""),46038.0) -> 46038 | C7: =IFERROR(__xludf.DUMMYFUNCTION("""COMPUTED_VALUE"""),46038.0) -> 46038 | D7: =IFERROR(__xludf.DUMMYFUNCTION("IF( A7="""", """", IFERROR( INDEX( FILTER( Data!$AA:$AA, Data!$C:$C=$A7, Data!$Q:$Q=$B7 ), 1 ), 0 ) )"),0.0) -> 0
A8: =IFERROR(__xludf.DUMMYFUNCTION("""COMPUTED_VALUE"""),"Sofia Martinez") -> Sofia Martinez | B8: =IFERROR(__xludf.DUMMYFUNCTION("""COMPUTED_VALUE"""),46038.0) -> 46038 | C8: =IFERROR(__xludf.DUMMYFUNCTION("""COMPUTED_VALUE"""),46038.0) -> 46038 | D8: =IFERROR(__xludf.DUMMYFUNCTION("IF( A8="""", """", IFERROR( INDEX( FILTER( Data!$AA:$AA, Data!$C:$C=$A8, Data!$Q:$Q=$B8 ), 1 ), 0 ) )"),0.0) -> 0
A9: =IFERROR(__xludf.DUMMYFUNCTION("""COMPUTED_VALUE"""),"Marcus Thompson") -> Marcus Thompson | B9: =IFERROR(__xludf.DUMMYFUNCTION("""COMPUTED_VALUE"""),46038.0) -> 46038 | C9: =IFERROR(__xludf.DUMMYFUNCTION("""COMPUTED_VALUE"""),46038.0) -> 46038 | D9: =IFERROR(__xludf.DUMMYFUNCTION("IF( A9="""", """", IFERROR( INDEX( FILTER( Data!$AA:$AA, Data!$C:$C=$A9, Data!$Q:$Q=$B9 ), 1 ), 0 ) )"),0.0) -> 0
A10: =IFERROR(__xludf.DUMMYFUNCTION("""COMPUTED_VALUE"""),"Priya Nair") -> Priya Nair | B10: =IFERROR(__xludf.DUMMYFUNCTION("""COMPUTED_VALUE"""),46038.0) -> 46038 | C10: =IFERROR(__xludf.DUMMYFUNCTION("""COMPUTED_VALUE"""),46038.0) -> 46038 | D10: =IFERROR(__xludf.DUMMYFUNCTION("IF( A10="""", """", IFERROR( INDEX( FILTER( Data!$AA:$AA, Data!$C:$C=$A10, Data!$Q:$Q=$B10 ), 1 ), 0 ) )"),0.0) -> 0
A11: =IFERROR(__xludf.DUMMYFUNCTION("""COMPUTED_VALUE"""),"Ethan Brooks") -> Ethan Brooks | B11: =IFERROR(__xludf.DUMMYFUNCTION("""COMPUTED_VALUE"""),46038.0) -> 46038 | C11: =IFERROR(__xludf.DUMMYFUNCTION("""COMPUTED_VALUE"""),46038.0) -> 46038 | D11: =IFERROR(__xludf.DUMMYFUNCTION("IF( A11="""", """", IFERROR( INDEX( FILTER( Data!$AA:$AA, Data!$C:$C=$A11, Data!$Q:$Q=$B11 ), 1 ), 0 ) )"),0.0) -> 0
A12: =IFERROR(__xludf.DUMMYFUNCTION("""COMPUTED_VALUE"""),"Fatima Hassan") -> Fatima Hassan | B12: =IFERROR(__xludf.DUMMYFUNCTION("""COMPUTED_VALUE"""),46038.0) -> 46038 | C12: =IFERROR(__xludf.DUMMYFUNCTION("""COMPUTED_VALUE"""),46038.0) -> 46038 | D12: =IFERROR(__xludf.DUMMYFUNCTION("IF( A12="""", """", IFERROR( INDEX( FILTER( Data!$AA:$AA, Data!$C:$C=$A12, Data!$Q:$Q=$B12 ), 1 ), 0 ) )"),0.0) -> 0
A13: =IFERROR(__xludf.DUMMYFUNCTION("""COMPUTED_VALUE"""),"Noah Levine") -> Noah Levine | B13: =IFERROR(__xludf.DUMMYFUNCTION("""COMPUTED_VALUE"""),46038.0) -> 46038 | C13: =IFERROR(__xludf.DUMMYFUNCTION("""COMPUTED_VALUE"""),46038.0) -> 46038 | D13: =IFERROR(__xludf.DUMMYFUNCTION("IF( A13="""", """", IFERROR( INDEX( FILTER( Data!$AA:$AA, Data!$C:$C=$A13, Data!$Q:$Q=$B13 ), 1 ), 0 ) )"),0.0) -> 0
A14: =IFERROR(__xludf.DUMMYFUNCTION("""COMPUTED_VALUE"""),"Grace Nguyen") -> Grace Nguyen | B14: =IFERROR(__xludf.DUMMYFUNCTION("""COMPUTED_VALUE"""),46038.0) -> 46038 | C14: =IFERROR(__xludf.DUMMYFUNCTION("""COMPUTED_VALUE"""),46038.0) -> 46038 | D14: =IFERROR(__xludf.DUMMYFUNCTION("IF( A14="""", """", IFERROR( INDEX( FILTER( Data!$AA:$AA, Data!$C:$C=$A14, Data!$Q:$Q=$B14 ), 1 ), 0 ) )"),0.0) -> 0
A15: =IFERROR(__xludf.DUMMYFUNCTION("""COMPUTED_VALUE"""),"Alejandro Cruz") -> Alejandro Cruz | B15: =IFERROR(__xludf.DUMMYFUNCTION("""COMPUTED_VALUE"""),46038.0) -> 46038 | C15: =IFERROR(__xludf.DUMMYFUNCTION("""COMPUTED_VALUE"""),46038.0) -> 46038 | D15: =IFERROR(__xludf.DUMMYFUNCTION("IF( A15="""", """", IFERROR( INDEX( FILTER( Data!$AA:$AA, Data!$C:$C=$A15, Data!$Q:$Q=$B15 ), 1 ), 0 ) )"),0.0) -> 0
A16: =IFERROR(__xludf.DUMMYFUNCTION("""COMPUTED_VALUE"""),"Aisha Johnson") -> Aisha Johnson | B16: =IFERROR(__xludf.DUMMYFUNCTION("""COMPUTED_VALUE"""),46045.0) -> 46045 | C16: =IFERROR(__xludf.DUMMYFUNCTION("""COMPUTED_VALUE"""),46052.0) -> 46052 | D16: =IFERROR(__xludf.DUMMYFUNCTION("IF( A16="""", """", IFERROR( INDEX( FILTER( Data!$AA:$AA, Data!$C:$C=$A16, Data!$Q:$Q=$B16 ), 1 ), 0 ) )"),100.0) -> 100
A17: =IFERROR(__xludf.DUMMYFUNCTION("""COMPUTED_VALUE"""),"Hannah O’Connor") -> Hannah O’Connor | B17: =IFERROR(__xludf.DUMMYFUNCTION("""COMPUTED_VALUE"""),46045.0) -> 46045 | C17: =IFERROR(__xludf.DUMMYFUNCTION("""COMPUTED_VALUE"""),46052.0) -> 46052 | D17: =IFERROR(__xludf.DUMMYFUNCTION("IF( A17="""", """", IFERROR( INDEX( FILTER( Data!$AA:$AA, Data!$C:$C=$A17, Data!$Q:$Q=$B17 ), 1 ), 0 ) )"),0.0) -> 0
A18: =IFERROR(__xludf.DUMMYFUNCTION("""COMPUTED_VALUE"""),"Jamal Washington") -> Jamal Washington | B18: =IFERROR(__xludf.DUMMYFUNCTION("""COMPUTED_VALUE"""),46045.0) -> 46045 | C18: =IFERROR(__xludf.DUMMYFUNCTION("""COMPUTED_VALUE"""),46052.0) -> 46052 | D18: =IFERROR(__xludf.DUMMYFUNCTION("IF( A18="""", """", IFERROR( INDEX( FILTER( Data!$AA:$AA, Data!$C:$C=$A18, Data!$Q:$Q=$B18 ), 1 ), 0 ) )"),0.0) -> 0
A19: =IFERROR(__xludf.DUMMYFUNCTION("""COMPUTED_VALUE"""),"Linh Tran") -> Linh Tran | B19: =IFERROR(__xludf.DUMMYFUNCTION("""COMPUTED_VALUE"""),46045.0) -> 46045 | C19: =IFERROR(__xludf.DUMMYFUNCTION("""COMPUTED_VALUE"""),46052.0) -> 46052 | D19: =IFERROR(__xludf.DUMMYFUNCTION("IF( A19="""", """", IFERROR( INDEX( FILTER( Data!$AA:$AA, Data!$C:$C=$A19, Data!$Q:$Q=$B19 ), 1 ), 0 ) )"),0.0) -> 0
A20: =IFERROR(__xludf.DUMMYFUNCTION("""COMPUTED_VALUE"""),"Olivia Bennett") -> Olivia Bennett | B20: =IFERROR(__xludf.DUMMYFUNCTION("""COMPUTED_VALUE"""),46045.0) -> 46045 | C20: =IFERROR(__xludf.DUMMYFUNCTION("""COMPUTED_VALUE"""),46052.0) -> 46052 | D20: =IFERROR(__xludf.DUMMYFUNCTION("IF( A20="""", """", IFERROR( INDEX( FILTER( Data!$AA:$AA, Data!$C:$C=$A20, Data!$Q:$Q=$B20 ), 1 ), 0 ) )"),0.0) -> 0
A21: =IFERROR(__xludf.DUMMYFUNCTION("""COMPUTED_VALUE"""),"Rohan Mehta") -> Rohan Mehta | B21: =IFERROR(__xludf.DUMMYFUNCTION("""COMPUTED_VALUE"""),46045.0) -> 46045 | C21: =IFERROR(__xludf.DUMMYFUNCTION("""COMPUTED_VALUE"""),46052.0) -> 46052 | D21: =IFERROR(__xludf.DUMMYFUNCTION("IF( A21="""", """", IFERROR( INDEX( FILTER( Data!$AA:$AA, Data!$C:$C=$A21, Data!$Q:$Q=$B21 ), 1 ), 0 ) )"),0.0) -> 0
A22: =IFERROR(__xludf.DUMMYFUNCTION("""COMPUTED_VALUE"""),"Isabella Flores") -> Isabella Flores | B22: =IFERROR(__xludf.DUMMYFUNCTION("""COMPUTED_VALUE"""),46045.0) -> 46045 | C22: =IFERROR(__xludf.DUMMYFUNCTION("""COMPUTED_VALUE"""),46052.0) -> 46052 | D22: =IFERROR(__xludf.DUMMYFUNCTION("IF( A22="""", """", IFERROR( INDEX( FILTER( Data!$AA:$AA, Data!$C:$C=$A22, Data!$Q:$Q=$B22 ), 1 ), 0 ) )"),100.0) -> 100
